// 代码生成时间: 2025-08-10 18:37:28
using System;
using Microsoft.VisualStudio.TestTools.UnitTesting;

// 定义测试类
[TestClass]
public class IntegrationTestTool
{
    // 测试方法：示例测试
    [TestMethod]
    [TestCategory("Integration")]
    public void TestExample()
    {
        // 测试逻辑
        try
        {
            // 假设我们要测试一个方法，例如获取当前日期
            var currentDate = DateTime.Now;

            // 检查日期是否为今天（只是一个示例）
            var expectedDate = DateTime.Today;
            Assert.AreEqual(expectedDate, currentDate.Date, "The current date should be today's date.");

            // 测试通过
            Console.WriteLine("Test passed: The current date is today's date.");
        }
        catch (Exception ex)
        {
            // 错误处理：记录异常信息
            Console.WriteLine($"Test failed with exception: {ex.Message}");
            throw;
        }
    }

    // 测试方法：另一个示例测试
    [TestMethod]
    [TestCategory("Integration")]
    public void TestAnotherExample()
    {
        // 测试逻辑
        try
        {
            // 假设我们要测试一个字符串是否不为空
            string testString = "Hello, World!";

            // 检查字符串是否不为空
            Assert.IsFalse(string.IsNullOrEmpty(testString), "The test string should not be empty.");

            // 测试通过
            Console.WriteLine("Test passed: The test string is not empty.");
        }
        catch (Exception ex)
        {
            // 错误处理：记录异常信息
            Console.WriteLine($"Test failed with exception: {ex.Message}");
            throw;
        }
    }

    // 测试方法：异常处理测试
    [TestMethod]
    [TestCategory("Integration")]
    public void TestExceptionHandling()
    {
        // 测试逻辑
        try
        {
            // 假设我们要测试一个可能抛出异常的方法
            // 为了演示，我们故意抛出一个异常
            throw new InvalidOperationException("Intentional exception for testing.");
        }
        catch (InvalidOperationException ex)
        {
            // 测试通过：捕获到预期的异常
            Console.WriteLine("Test passed: Caught an InvalidOperationException as expected.");
            Assert.IsTrue(ex.Message.Contains("Intentional exception for testing."), "The exception message should contain 'Intentional exception for testing.'");
        }
        catch (Exception ex)
        {
            // 错误处理：记录异常信息
            Console.WriteLine($"Test failed with unexpected exception: {ex.Message}");
            throw;
        }
    }
}
